Workbook

Sheet SCAs
C2: DADOS DO PROJETO | D2: UNIDADE: | E2: RONDONÓPOLIS/MT | H2: LEGENDA: | M2: RESUMO GERAL | N2: TOTAL ILHAS | O2: {=SUMPRODUCT((Tabela1[Ilha de Processo]<>"")/COUNTIF(Tabela1[Ilha de Processo],Tabela1[Ilha de Processo]&""))} -> 19
D3: FASE(S): | E3: 1 e 2 | H3: CÓDIGO DA EAP | N3: TOTAL DE SCAs | O3: =COUNTA(Tabela1[Sistema de Controle Ambiental]) -> 0
D4: CONTEÚDO DO DOC.: | E4: SISTEMAS DE CONTROLE AMBIENTAL | H4: LINHA DE BASE (LB) | N4: Não iniciado | O4: =COUNTIF(Tabela1[Situação],$N4) -> 0
D5: NOME DO DOC.: | E5: MAM_CHECKLIST_SCA_RND-V02 | H5: PREENCHIMENTO MANUAL ÚNICO (1x) | N5: Em andamento | O5: =COUNTIF(Tabela1[Situação],$N5) -> 0
D6: RESPONSÁVEL DA UND: | H6: FÓRMULA AUTOMÁTICA | N6: Concluído | O6: =COUNTIF(Tabela1[Situação],$N6) -> 0
D7: ÚLTIMA ATUALIZAÇÃO: | H7: PREENCHIMENTO MANUAL | N7: % A CONCLUIR | O7: =SUM(O4:O5)/O$3 -> #DIV/0!
A9: Cód. do Processo - Engenharia | B9: Macro área | C9: Ilha de Processo | D9: Processo | E9: Área Descrição MAM | F9: Fase | G9: Prazo p/ vistoria | H9: Previsto (LB) | I9: Replan | J9: Qtde de replans | K9: Desvio (dias) | L9: Cód. EAP | M9: Sistema de Controle Ambiental | N9: SCA Macro | O9: Disciplina | P9: Supervisor responsável | Q9: Gerente responsável | R9: Situação | S9: Alerta | T9: Observação
A10: =_xlfn.XLOOKUP("*"&Tabela1[[#This Row],[Processo]]&"*",'Árvore de Localização'!$H:$H,'Árvore de Localização'!$G:$G,"0000",2) -> 2123.F | B10: =_xlfn.XLOOKUP(Tabela1[[#This Row],[Processo]],'Árvore de Localização'!$D:$D,'Árvore de Localização'!$B:$B,"",0,1) -> Administração | C10: =_xlfn.XLOOKUP(Tabela1[[#This Row],[Processo]],'Árvore de Localização'!$D:$D,'Árvore de Localização'!$C:$C,"",0,1) -> Administração | D10: Almoxarifado | E10: Almoxarifado | F10: 1 | K10: =IF(OR(Tabela1[[#This Row],[Replan]]="",Tabela1[[#This Row],[Previsto (LB)]]=""),"",Tabela1[[#This Row],[Previsto (LB)]]-Tabela1[[#This Row],[Replan]]) | L10: 1.2.20.1.1 | S10: =IF(R10="Não iniciado",1,IF(R10="Em andamento",2,3)) -> 3
A11: =_xlfn.XLOOKUP("*"&Tabela1[[#This Row],[Processo]]&"*",'Árvore de Localização'!$H:$H,'Árvore de Localização'!$G:$G,"0000",2) -> 2123.F | B11: =_xlfn.XLOOKUP(Tabela1[[#This Row],[Processo]],'Árvore de Localização'!$D:$D,'Árvore de Localização'!$B:$B,"",0,1) -> Administração | C11: =_xlfn.XLOOKUP(Tabela1[[#This Row],[Processo]],'Árvore de Localização'!$D:$D,'Árvore de Localização'!$C:$C,"",0,1) -> Administração | D11: Almoxarifado | E11: Almoxarifado | F11: 1 | K11: =IF(OR(Tabela1[[#This Row],[Replan]]="",Tabela1[[#This Row],[Previsto (LB)]]=""),"",Tabela1[[#This Row],[Previsto (LB)]]-Tabela1[[#This Row],[Replan]]) | L11: 1.2.20.1.2 | S11: =IF(R11="Não iniciado",1,IF(R11="Em andamento",2,3)) -> 3
A12: =_xlfn.XLOOKUP("*"&Tabela1[[#This Row],[Processo]]&"*",'Árvore de Localização'!$H:$H,'Árvore de Localização'!$G:$G,"0000",2) -> 2123.F | B12: =_xlfn.XLOOKUP(Tabela1[[#This Row],[Processo]],'Árvore de Localização'!$D:$D,'Árvore de Localização'!$B:$B,"",0,1) -> Administração | C12: =_xlfn.XLOOKUP(Tabela1[[#This Row],[Processo]],'Árvore de Localização'!$D:$D,'Árvore de Localização'!$C:$C,"",0,1) -> Administração | D12: Almoxarifado | E12: Almoxarifado | F12: 1 | K12: =IF(OR(Tabela1[[#This Row],[Replan]]="",Tabela1[[#This Row],[Previsto (LB)]]=""),"",Tabela1[[#This Row],[Previsto (LB)]]-Tabela1[[#This Row],[Replan]]) | L12: 1.2.20.2.1 | S12: =IF(R12="Não iniciado",1,IF(R12="Em andamento",2,3)) -> 3
A13: =_xlfn.XLOOKUP("*"&Tabela1[[#This Row],[Processo]]&"*",'Árvore de Localização'!$H:$H,'Árvore de Localização'!$G:$G,"0000",2) -> 2109.C | B13: =_xlfn.XLOOKUP(Tabela1[[#This Row],[Processo]],'Árvore de Localização'!$D:$D,'Árvore de Localização'!$B:$B,"",0,1) -> DDGSeÓleo | C13: =_xlfn.XLOOKUP(Tabela1[[#This Row],[Processo]],'Árvore de Localização'!$D:$D,'Árvore de Localização'!$C:$C,"",0,1) -> Separação de Sólidos e Secagem de DDGS | D13: Armazenamento e Expedição de DDGS | E13: Armazém de DDGS | F13: 1 | K13: =IF(OR(Tabela1[[#This Row],[Replan]]="",Tabela1[[#This Row],[Previsto (LB)]]=""),"",Tabela1[[#This Row],[Previsto (LB)]]-Tabela1[[#This Row],[Replan]]) | L13: 1.2.7.1.1 | S13: =IF(R13="Não iniciado",1,IF(R13="Em andamento",2,3)) -> 3
A14: =_xlfn.XLOOKUP("*"&Tabela1[[#This Row],[Processo]]&"*",'Árvore de Localização'!$H:$H,'Árvore de Localização'!$G:$G,"0000",2) -> 2109.C | B14: =_xlfn.XLOOKUP(Tabela1[[#This Row],[Processo]],'Árvore de Localização'!$D:$D,'Árvore de Localização'!$B:$B,"",0,1) -> DDGSeÓleo | C14: =_xlfn.XLOOKUP(Tabela1[[#This Row],[Processo]],'Árvore de Localização'!$D:$D,'Árvore de Localização'!$C:$C,"",0,1) -> Separação de Sólidos e Secagem de DDGS | D14: Armazenamento e Expedição de DDGS | E14: Armazém de DDGS | F14: 1 | K14: =IF(OR(Tabela1[[#This Row],[Replan]]="",Tabela1[[#This Row],[Previsto (LB)]]=""),"",Tabela1[[#This Row],[Previsto (LB)]]-Tabela1[[#This Row],[Replan]]) | L14: 1.2.7.1.2 | S14: =IF(R14="Não iniciado",1,IF(R14="Em andamento",2,3)) -> 3
A15: =_xlfn.XLOOKUP("*"&Tabela1[[#This Row],[Processo]]&"*",'Árvore de Localização'!$H:$H,'Árvore de Localização'!$G:$G,"0000",2) -> 2109.C | B15: =_xlfn.XLOOKUP(Tabela1[[#This Row],[Processo]],'Árvore de Localização'!$D:$D,'Árvore de Localização'!$B:$B,"",0,1) -> DDGSeÓleo | C15: =_xlfn.XLOOKUP(Tabela1[[#This Row],[Processo]],'Árvore de Localização'!$D:$D,'Árvore de Localização'!$C:$C,"",0,1) -> Separação de Sólidos e Secagem de DDGS | D15: Armazenamento e Expedição de DDGS | E15: Armazém de DDGS | F15: 1 | K15: =IF(OR(Tabela1[[#This Row],[Replan]]="",Tabela1[[#This Row],[Previsto (LB)]]=""),"",Tabela1[[#This Row],[Previsto (LB)]]-Tabela1[[#This Row],[Replan]]) | L15: 1.2.7.1.3 | S15: =IF(R15="Não iniciado",1,IF(R15="Em andamento",2,3)) -> 3
A16: =_xlfn.XLOOKUP("*"&Tabela1[[#This Row],[Processo]]&"*",'Árvore de Localização'!$H:$H,'Árvore de Localização'!$G:$G,"0000",2) -> 2119. | B16: =_xlfn.XLOOKUP(Tabela1[[#This Row],[Processo]],'Árvore de Localização'!$D:$D,'Árvore de Localização'!$B:$B,"",0,1) -> Grãos | C16: =_xlfn.XLOOKUP(Tabela1[[#This Row],[Processo]],'Árvore de Localização'!$D:$D,'Árvore de Localização'!$C:$C,"",0,1) -> Descarregamento e Armazenamento de Grãos | D16: Armazenamento de Grãos | E16: Armazém de Milho | F16: 1 | K16: =IF(OR(Tabela1[[#This Row],[Replan]]="",Tabela1[[#This Row],[Previsto (LB)]]=""),"",Tabela1[[#This Row],[Previsto (LB)]]-Tabela1[[#This Row],[Replan]]) | L16: 1.2.19.1.1 | S16: =IF(R16="Não iniciado",1,IF(R16="Em andamento",2,3)) -> 3
A17: =_xlfn.XLOOKUP("*"&Tabela1[[#This Row],[Processo]]&"*",'Árvore de Localização'!$H:$H,'Árvore de Localização'!$G:$G,"0000",2) -> 2119. | B17: =_xlfn.XLOOKUP(Tabela1[[#This Row],[Processo]],'Árvore de Localização'!$D:$D,'Árvore de Localização'!$B:$B,"",0,1) -> Grãos | C17: =_xlfn.XLOOKUP(Tabela1[[#This Row],[Processo]],'Árvore de Localização'!$D:$D,'Árvore de Localização'!$C:$C,"",0,1) -> Descarregamento e Armazenamento de Grãos | D17: Armazenamento de Grãos | E17: Armazém de Milho | F17: 1 | K17: =IF(OR(Tabela1[[#This Row],[Replan]]="",Tabela1[[#This Row],[Previsto (LB)]]=""),"",Tabela1[[#This Row],[Previsto (LB)]]-Tabela1[[#This Row],[Replan]]) | L17: 1.2.19.1.2 | S17: =IF(R17="Não iniciado",1,IF(R17="Em andamento",2,3)) -> 3
A18: =_xlfn.XLOOKUP("*"&Tabela1[[#This Row],[Processo]]&"*",'Árvore de Localização'!$H:$H,'Árvore de Localização'!$G:$G,"0000",2) -> 2119. | B18: =_xlfn.XLOOKUP(Tabela1[[#This Row],[Processo]],'Árvore de Localização'!$D:$D,'Árvore de Localização'!$B:$B,"",0,1) -> Grãos | C18: =_xlfn.XLOOKUP(Tabela1[[#This Row],[Processo]],'Árvore de Localização'!$D:$D,'Árvore de Localização'!$C:$C,"",0,1) -> Descarregamento e Armazenamento de Grãos | D18: Armazenamento de Grãos | E18: Armazém de Milho | F18: 1 | K18: =IF(OR(Tabela1[[#This Row],[Replan]]="",Tabela1[[#This Row],[Previsto (LB)]]=""),"",Tabela1[[#This Row],[Previsto (LB)]]-Tabela1[[#This Row],[Replan]]) | L18: 1.2.19.1.3 | S18: =IF(R18="Não iniciado",1,IF(R18="Em andamento",2,3)) -> 3
A19: =_xlfn.XLOOKUP("*"&Tabela1[[#This Row],[Processo]]&"*",'Árvore de Localização'!$H:$H,'Árvore de Localização'!$G:$G,"0000",2) -> 2100.C | B19: =_xlfn.XLOOKUP(Tabela1[[#This Row],[Processo]],'Árvore de Localização'!$D:$D,'Árvore de Localização'!$B:$B,"",0,1) -> Geral | C19: =_xlfn.XLOOKUP(Tabela1[[#This Row],[Processo]],'Árvore de Localização'!$D:$D,'Árvore de Localização'!$C:$C,"",0,1) -> Geral | D19: Drenagem | E19: Bacia Pluvial | F19: Ambas | K19: =IF(OR(Tabela1[[#This Row],[Replan]]="",Tabela1[[#This Row],[Previsto (LB)]]=""),"",Tabela1[[#This Row],[Previsto (LB)]]-Tabela1[[#This Row],[Replan]]) | L19: 1.2.1.1.1 | S19: =IF(R19="Não iniciado",1,IF(R19="Em andamento",2,3)) -> 3
A20: =_xlfn.XLOOKUP("*"&Tabela1[[#This Row],[Processo]]&"*",'Árvore de Localização'!$H:$H,'Árvore de Localização'!$G:$G,"0000",2) -> 2100.C | B20: =_xlfn.XLOOKUP(Tabela1[[#This Row],[Processo]],'Árvore de Localização'!$D:$D,'Árvore de Localização'!$B:$B,"",0,1) -> Geral | C20: =_xlfn.XLOOKUP(Tabela1[[#This Row],[Processo]],'Árvore de Localização'!$D:$D,'Árvore de Localização'!$C:$C,"",0,1) -> Geral | D20: Drenagem | E20: Bacia Pluvial | F20: Ambas | K20: =IF(OR(Tabela1[[#This Row],[Replan]]="",Tabela1[[#This Row],[Previsto (LB)]]=""),"",Tabela1[[#This Row],[Previsto (LB)]]-Tabela1[[#This Row],[Replan]]) | L20: 1.2.1.1.2 | S20: =IF(R20="Não iniciado",1,IF(R20="Em andamento",2,3)) -> 3
A21: =_xlfn.XLOOKUP("*"&Tabela1[[#This Row],[Processo]]&"*",'Árvore de Localização'!$H:$H,'Árvore de Localização'!$G:$G,"0000",2) -> 2100.C | B21: =_xlfn.XLOOKUP(Tabela1[[#This Row],[Processo]],'Árvore de Localização'!$D:$D,'Árvore de Localização'!$B:$B,"",0,1) -> Geral | C21: =_xlfn.XLOOKUP(Tabela1[[#This Row],[Processo]],'Árvore de Localização'!$D:$D,'Árvore de Localização'!$C:$C,"",0,1) -> Geral | D21: Drenagem | E21: Bacia Pluvial | F21: Ambas | K21: =IF(OR(Tabela1[[#This Row],[Replan]]="",Tabela1[[#This Row],[Previsto (LB)]]=""),"",Tabela1[[#This Row],[Previsto (LB)]]-Tabela1[[#This Row],[Replan]]) | L21: 1.2.1.1.3 | S21: =IF(R21="Não iniciado",1,IF(R21="Em andamento",2,3)) -> 3
A22: =_xlfn.XLOOKUP("*"&Tabela1[[#This Row],[Processo]]&"*",'Árvore de Localização'!$H:$H,'Árvore de Localização'!$G:$G,"0000",2) -> 2100.C | B22: =_xlfn.XLOOKUP(Tabela1[[#This Row],[Processo]],'Árvore de Localização'!$D:$D,'Árvore de Localização'!$B:$B,"",0,1) -> Geral | C22: =_xlfn.XLOOKUP(Tabela1[[#This Row],[Processo]],'Árvore de Localização'!$D:$D,'Árvore de Localização'!$C:$C,"",0,1) -> Geral | D22: Drenagem | E22: Bacia Pluvial | F22: Ambas | K22: =IF(OR(Tabela1[[#This Row],[Replan]]="",Tabela1[[#This Row],[Previsto (LB)]]=""),"",Tabela1[[#This Row],[Previsto (LB)]]-Tabela1[[#This Row],[Replan]]) | L22: 1.2.1.1.4 | S22: =IF(R22="Não iniciado",1,IF(R22="Em andamento",2,3)) -> 3
A23: =_xlfn.XLOOKUP("*"&Tabela1[[#This Row],[Processo]]&"*",'Árvore de Localização'!$H:$H,'Árvore de Localização'!$G:$G,"0000",2) -> 2100.C | B23: =_xlfn.XLOOKUP(Tabela1[[#This Row],[Processo]],'Árvore de Localização'!$D:$D,'Árvore de Localização'!$B:$B,"",0,1) -> Geral | C23: =_xlfn.XLOOKUP(Tabela1[[#This Row],[Processo]],'Árvore de Localização'!$D:$D,'Árvore de Localização'!$C:$C,"",0,1) -> Geral | D23: Drenagem | E23: Bacia Pluvial | F23: Ambas | K23: =IF(OR(Tabela1[[#This Row],[Replan]]="",Tabela1[[#This Row],[Previsto (LB)]]=""),"",Tabela1[[#This Row],[Previsto (LB)]]-Tabela1[[#This Row],[Replan]]) | L23: 1.2.1.3.1 | S23: =IF(R23="Não iniciado",1,IF(R23="Em andamento",2,3)) -> 3
A24: =_xlfn.XLOOKUP("*"&Tabela1[[#This Row],[Processo]]&"*",'Árvore de Localização'!$H:$H,'Árvore de Localização'!$G:$G,"0000",2) -> 2100.C | B24: =_xlfn.XLOOKUP(Tabela1[[#This Row],[Processo]],'Árvore de Localização'!$D:$D,'Árvore de Localização'!$B:$B,"",0,1) -> Geral | C24: =_xlfn.XLOOKUP(Tabela1[[#This Row],[Processo]],'Árvore de Localização'!$D:$D,'Árvore de Localização'!$C:$C,"",0,1) -> Geral | D24: Drenagem | E24: Bacia Pluvial | F24: Ambas | K24: =IF(OR(Tabela1[[#This Row],[Replan]]="",Tabela1[[#This Row],[Previsto (LB)]]=""),"",Tabela1[[#This Row],[Previsto (LB)]]-Tabela1[[#This Row],[Replan]]) | L24: 1.2.1.1.5 | S24: =IF(R24="Não iniciado",1,IF(R24="Em andamento",2,3)) -> 3
A25: =_xlfn.XLOOKUP("*"&Tabela1[[#This Row],[Processo]]&"*",'Árvore de Localização'!$H:$H,'Árvore de Localização'!$G:$G,"0000",2) -> 2110.D | B25: =_xlfn.XLOOKUP(Tabela1[[#This Row],[Processo]],'Árvore de Localização'!$D:$D,'Árvore de Localização'!$B:$B,"",0,1) -> Utilidades | C25: =_xlfn.XLOOKUP(Tabela1[[#This Row],[Processo]],'Árvore de Localização'!$D:$D,'Árvore de Localização'!$C:$C,"",0,1) -> Estação de Tratamento de Água (ETA) | D25: Água Potável | E25: Caixa d'água | F25: Ambas | K25: =IF(OR(Tabela1[[#This Row],[Replan]]="",Tabela1[[#This Row],[Previsto (LB)]]=""),"",Tabela1[[#This Row],[Previsto (LB)]]-Tabela1[[#This Row],[Replan]]) | L25: 1.2.14.1.1 | S25: =IF(R25="Não iniciado",1,IF(R25="Em andamento",2,3)) -> 3
A26: =_xlfn.XLOOKUP("*"&Tabela1[[#This Row],[Processo]]&"*",'Árvore de Localização'!$H:$H,'Árvore de Localização'!$G:$G,"0000",2) -> 2110.D | B26: =_xlfn.XLOOKUP(Tabela1[[#This Row],[Processo]],'Árvore de Localização'!$D:$D,'Árvore de Localização'!$B:$B,"",0,1) -> Utilidades | C26: =_xlfn.XLOOKUP(Tabela1[[#This Row],[Processo]],'Árvore de Localização'!$D:$D,'Árvore de Localização'!$C:$C,"",0,1) -> Estação de Tratamento de Água (ETA) | D26: Água Potável | E26: Caixa d'água | F26: Ambas | K26: =IF(OR(Tabela1[[#This Row],[Replan]]="",Tabela1[[#This Row],[Previsto (LB)]]=""),"",Tabela1[[#This Row],[Previsto (LB)]]-Tabela1[[#This Row],[Replan]]) | L26: 1.2.14.3.1 | S26: =IF(R26="Não iniciado",1,IF(R26="Em andamento",2,3)) -> 3
A27: =_xlfn.XLOOKUP("*"&Tabela1[[#This Row],[Processo]]&"*",'Árvore de Localização'!$H:$H,'Árvore de Localização'!$G:$G,"0000",2) -> 2110.D | B27: =_xlfn.XLOOKUP(Tabela1[[#This Row],[Processo]],'Árvore de Localização'!$D:$D,'Árvore de Localização'!$B:$B,"",0,1) -> Utilidades | C27: =_xlfn.XLOOKUP(Tabela1[[#This Row],[Processo]],'Árvore de Localização'!$D:$D,'Árvore de Localização'!$C:$C,"",0,1) -> Estação de Tratamento de Água (ETA) | D27: Água Potável | E27: Caixa d'água | F27: Ambas | K27: =IF(OR(Tabela1[[#This Row],[Replan]]="",Tabela1[[#This Row],[Previsto (LB)]]=""),"",Tabela1[[#This Row],[Previsto (LB)]]-Tabela1[[#This Row],[Replan]]) | L27: 1.2.14.1.2 | S27: =IF(R27="Não iniciado",1,IF(R27="Em andamento",2,3)) -> 3
A28: =_xlfn.XLOOKUP("*"&Tabela1[[#This Row],[Processo]]&"*",'Árvore de Localização'!$H:$H,'Árvore de Localização'!$G:$G,"0000",2) -> 2110.D | B28: =_xlfn.XLOOKUP(Tabela1[[#This Row],[Processo]],'Árvore de Localização'!$D:$D,'Árvore de Localização'!$B:$B,"",0,1) -> Utilidades | C28: =_xlfn.XLOOKUP(Tabela1[[#This Row],[Processo]],'Árvore de Localização'!$D:$D,'Árvore de Localização'!$C:$C,"",0,1) -> Estação de Tratamento de Água (ETA) | D28: Água Potável | E28: Caixa d'água | F28: Ambas | K28: =IF(OR(Tabela1[[#This Row],[Replan]]="",Tabela1[[#This Row],[Previsto (LB)]]=""),"",Tabela1[[#This Row],[Previsto (LB)]]-Tabela1[[#This Row],[Replan]]) | L28: 1.2.14.1.3 | S28: =IF(R28="Não iniciado",1,IF(R28="Em andamento",2,3)) -> 3
A29: =_xlfn.XLOOKUP("*"&Tabela1[[#This Row],[Processo]]&"*",'Árvore de Localização'!$H:$H,'Árvore de Localização'!$G:$G,"0000",2) -> 2101.A | B29: =_xlfn.XLOOKUP(Tabela1[[#This Row],[Processo]],'Árvore de Localização'!$D:$D,'Árvore de Localização'!$B:$B,"",0,1) -> Utilidades | C29: =_xlfn.XLOOKUP(Tabela1[[#This Row],[Processo]],'Árvore de Localização'!$D:$D,'Árvore de Localização'!$C:$C,"",0,1) -> Geração de Vapor | D29: Caldeira | E29: Caldeira | F29: 1 | K29: =IF(OR(Tabela1[[#This Row],[Replan]]="",Tabela1[[#This Row],[Previsto (LB)]]=""),"",Tabela1[[#This Row],[Previsto (LB)]]-Tabela1[[#This Row],[Replan]]) | L29: 1.2.11.1.1 | S29: =IF(R29="Não iniciado",1,IF(R29="Em andamento",2,3)) -> 3
A30: =_xlfn.XLOOKUP("*"&Tabela1[[#This Row],[Processo]]&"*",'Árvore de Localização'!$H:$H,'Árvore de Localização'!$G:$G,"0000",2) -> 2101.A | B30: =_xlfn.XLOOKUP(Tabela1[[#This Row],[Processo]],'Árvore de Localização'!$D:$D,'Árvore de Localização'!$B:$B,"",0,1) -> Utilidades | C30: =_xlfn.XLOOKUP(Tabela1[[#This Row],[Processo]],'Árvore de Localização'!$D:$D,'Árvore de Localização'!$C:$C,"",0,1) -> Geração de Vapor | D30: Caldeira | E30: Caldeira | F30: 1 | K30: =IF(OR(Tabela1[[#This Row],[Replan]]="",Tabela1[[#This Row],[Previsto (LB)]]=""),"",Tabela1[[#This Row],[Previsto (LB)]]-Tabela1[[#This Row],[Replan]]) | L30: 1.2.11.3.1 | S30: =IF(R30="Não iniciado",1,IF(R30="Em andamento",2,3)) -> 3
A31: =_xlfn.XLOOKUP("*"&Tabela1[[#This Row],[Processo]]&"*",'Árvore de Localização'!$H:$H,'Árvore de Localização'!$G:$G,"0000",2) -> 2101.A | B31: =_xlfn.XLOOKUP(Tabela1[[#This Row],[Processo]],'Árvore de Localização'!$D:$D,'Árvore de Localização'!$B:$B,"",0,1) -> Utilidades | C31: =_xlfn.XLOOKUP(Tabela1[[#This Row],[Processo]],'Árvore de Localização'!$D:$D,'Árvore de Localização'!$C:$C,"",0,1) -> Geração de Vapor | D31: Caldeira | E31: Caldeira | F31: 1 | K31: =IF(OR(Tabela1[[#This Row],[Replan]]="",Tabela1[[#This Row],[Previsto (LB)]]=""),"",Tabela1[[#This Row],[Previsto (LB)]]-Tabela1[[#This Row],[Replan]]) | L31: 1.2.11.2.1 | S31: =IF(R31="Não iniciado",1,IF(R31="Em andamento",2,3)) -> 3
A32: =_xlfn.XLOOKUP("*"&Tabela1[[#This Row],[Processo]]&"*",'Árvore de Localização'!$H:$H,'Árvore de Localização'!$G:$G,"0000",2) -> 2101.A | B32: =_xlfn.XLOOKUP(Tabela1[[#This Row],[Processo]],'Árvore de Localização'!$D:$D,'Árvore de Localização'!$B:$B,"",0,1) -> Utilidades | C32: =_xlfn.XLOOKUP(Tabela1[[#This Row],[Processo]],'Árvore de Localização'!$D:$D,'Árvore de Localização'!$C:$C,"",0,1) -> Geração de Vapor | D32: Caldeira | E32: Caldeira | F32: 1 | K32: =IF(OR(Tabela1[[#This Row],[Replan]]="",Tabela1[[#This Row],[Previsto (LB)]]=""),"",Tabela1[[#This Row],[Previsto (LB)]]-Tabela1[[#This Row],[Replan]]) | L32: 1.2.11.5.1 | S32: =IF(R32="Não iniciado",1,IF(R32="Em andamento",2,3)) -> 3
A33: =_xlfn.XLOOKUP("*"&Tabela1[[#This Row],[Processo]]&"*",'Árvore de Localização'!$H:$H,'Árvore de Localização'!$G:$G,"0000",2) -> 2101.A | B33: =_xlfn.XLOOKUP(Tabela1[[#This Row],[Processo]],'Árvore de Localização'!$D:$D,'Árvore de Localização'!$B:$B,"",0,1) -> Utilidades | C33: =_xlfn.XLOOKUP(Tabela1[[#This Row],[Processo]],'Árvore de Localização'!$D:$D,'Árvore de Localização'!$C:$C,"",0,1) -> Geração de Vapor | D33: Caldeira | E33: Caldeira | F33: 1 | K33: =IF(OR(Tabela1[[#This Row],[Replan]]="",Tabela1[[#This Row],[Previsto (LB)]]=""),"",Tabela1[[#This Row],[Previsto (LB)]]-Tabela1[[#This Row],[Replan]]) | L33: 1.2.11.1.2 | S33: =IF(R33="Não iniciado",1,IF(R33="Em andamento",2,3)) -> 3
A34: =_xlfn.XLOOKUP("*"&Tabela1[[#This Row],[Processo]]&"*",'Árvore de Localização'!$H:$H,'Árvore de Localização'!$G:$G,"0000",2) -> 2101.A | B34: =_xlfn.XLOOKUP(Tabela1[[#This Row],[Processo]],'Árvore de Localização'!$D:$D,'Árvore de Localização'!$B:$B,"",0,1) -> Utilidades | C34: =_xlfn.XLOOKUP(Tabela1[[#This Row],[Processo]],'Árvore de Localização'!$D:$D,'Árvore de Localização'!$C:$C,"",0,1) -> Geração de Vapor | D34: Caldeira | E34: Caldeira | F34: 1 | K34: =IF(OR(Tabela1[[#This Row],[Replan]]="",Tabela1[[#This Row],[Previsto (LB)]]=""),"",Tabela1[[#This Row],[Previsto (LB)]]-Tabela1[[#This Row],[Replan]]) | L34: 1.2.11.2.2 | S34: =IF(R34="Não iniciado",1,IF(R34="Em andamento",2,3)) -> 3
A35: =_xlfn.XLOOKUP("*"&Tabela1[[#This Row],[Processo]]&"*",'Árvore de Localização'!$H:$H,'Árvore de Localização'!$G:$G,"0000",2) -> 2101.A | B35: =_xlfn.XLOOKUP(Tabela1[[#This Row],[Processo]],'Árvore de Localização'!$D:$D,'Árvore de Localização'!$B:$B,"",0,1) -> Utilidades | C35: =_xlfn.XLOOKUP(Tabela1[[#This Row],[Processo]],'Árvore de Localização'!$D:$D,'Árvore de Localização'!$C:$C,"",0,1) -> Geração de Vapor | D35: Caldeira | E35: Caldeira | F35: 1 | K35: =IF(OR(Tabela1[[#This Row],[Replan]]="",Tabela1[[#This Row],[Previsto (LB)]]=""),"",Tabela1[[#This Row],[Previsto (LB)]]-Tabela1[[#This Row],[Replan]]) | L35: 1.2.11.1.3 | S35: =IF(R35="Não iniciado",1,IF(R35="Em andamento",2,3)) -> 3
A36: =_xlfn.XLOOKUP("*"&Tabela1[[#This Row],[Processo]]&"*",'Árvore de Localização'!$H:$H,'Árvore de Localização'!$G:$G,"0000",2) -> 2101.A | B36: =_xlfn.XLOOKUP(Tabela1[[#This Row],[Processo]],'Árvore de Localização'!$D:$D,'Árvore de Localização'!$B:$B,"",0,1) -> Utilidades | C36: =_xlfn.XLOOKUP(Tabela1[[#This Row],[Processo]],'Árvore de Localização'!$D:$D,'Árvore de Localização'!$C:$C,"",0,1) -> Geração de Vapor | D36: Caldeira | E36: Caldeira | F36: 1 | K36: =IF(OR(Tabela1[[#This Row],[Replan]]="",Tabela1[[#This Row],[Previsto (LB)]]=""),"",Tabela1[[#This Row],[Previsto (LB)]]-Tabela1[[#This Row],[Replan]]) | L36: 1.2.11.3.2 | S36: =IF(R36="Não iniciado",1,IF(R36="Em andamento",2,3)) -> 3
A37: =_xlfn.XLOOKUP("*"&Tabela1[[#This Row],[Processo]]&"*",'Árvore de Localização'!$H:$H,'Árvore de Localização'!$G:$G,"0000",2) -> 2101.A | B37: =_xlfn.XLOOKUP(Tabela1[[#This Row],[Processo]],'Árvore de Localização'!$D:$D,'Árvore de Localização'!$B:$B,"",0,1) -> Utilidades | C37: =_xlfn.XLOOKUP(Tabela1[[#This Row],[Processo]],'Árvore de Localização'!$D:$D,'Árvore de Localização'!$C:$C,"",0,1) -> Geração de Vapor | D37: Caldeira | E37: Caldeira | F37: 1 | K37: =IF(OR(Tabela1[[#This Row],[Replan]]="",Tabela1[[#This Row],[Previsto (LB)]]=""),"",Tabela1[[#This Row],[Previsto (LB)]]-Tabela1[[#This Row],[Replan]]) | L37: 1.2.11.2.3 | S37: =IF(R37="Não iniciado",1,IF(R37="Em andamento",2,3)) -> 3
A38: =_xlfn.XLOOKUP("*"&Tabela1[[#This Row],[Processo]]&"*",'Árvore de Localização'!$H:$H,'Árvore de Localização'!$G:$G,"0000",2) -> 2101.A | B38: =_xlfn.XLOOKUP(Tabela1[[#This Row],[Processo]],'Árvore de Localização'!$D:$D,'Árvore de Localização'!$B:$B,"",0,1) -> Utilidades | C38: =_xlfn.XLOOKUP(Tabela1[[#This Row],[Processo]],'Árvore de Localização'!$D:$D,'Árvore de Localização'!$C:$C,"",0,1) -> Geração de Vapor | D38: Caldeira | E38: Caldeira | F38: 1 | K38: =IF(OR(Tabela1[[#This Row],[Replan]]="",Tabela1[[#This Row],[Previsto (LB)]]=""),"",Tabela1[[#This Row],[Previsto (LB)]]-Tabela1[[#This Row],[Replan]]) | L38: 1.2.11.1.4 | S38: =IF(R38="Não iniciado",1,IF(R38="Em andamento",2,3)) -> 3
A39: =_xlfn.XLOOKUP("*"&Tabela1[[#This Row],[Processo]]&"*",'Árvore de Localização'!$H:$H,'Árvore de Localização'!$G:$G,"0000",2) -> 2104.A | B39: =_xlfn.XLOOKUP(Tabela1[[#This Row],[Processo]],'Árvore de Localização'!$D:$D,'Árvore de Localização'!$B:$B,"",0,1) -> Utilidades | C39: =_xlfn.XLOOKUP(Tabela1[[#This Row],[Processo]],'Árvore de Localização'!$D:$D,'Árvore de Localização'!$C:$C,"",0,1) -> Geração de Energia | D39: Casa de Força | E39: Casa de Força | F39: Ambas | K39: =IF(OR(Tabela1[[#This Row],[Replan]]="",Tabela1[[#This Row],[Previsto (LB)]]=""),"",Tabela1[[#This Row],[Previsto (LB)]]-Tabela1[[#This Row],[Replan]]) | L39: 1.2.12.1.1 | S39: =IF(R39="Não iniciado",1,IF(R39="Em andamento",2,3)) -> 3
A40: =_xlfn.XLOOKUP("*"&Tabela1[[#This Row],[Processo]]&"*",'Árvore de Localização'!$H:$H,'Árvore de Localização'!$G:$G,"0000",2) -> 2104.A | B40: =_xlfn.XLOOKUP(Tabela1[[#This Row],[Processo]],'Árvore de Localização'!$D:$D,'Árvore de Localização'!$B:$B,"",0,1) -> Utilidades | C40: =_xlfn.XLOOKUP(Tabela1[[#This Row],[Processo]],'Árvore de Localização'!$D:$D,'Árvore de Localização'!$C:$C,"",0,1) -> Geração de Energia | D40: Casa de Força | E40: Casa de Força | F40: Ambas | K40: =IF(OR(Tabela1[[#This Row],[Replan]]="",Tabela1[[#This Row],[Previsto (LB)]]=""),"",Tabela1[[#This Row],[Previsto (LB)]]-Tabela1[[#This Row],[Replan]]) | L40: 1.2.12.2.1 | S40: =IF(R40="Não iniciado",1,IF(R40="Em andamento",2,3)) -> 3
A41: =_xlfn.XLOOKUP("*"&Tabela1[[#This Row],[Processo]]&"*",'Árvore de Localização'!$H:$H,'Árvore de Localização'!$G:$G,"0000",2) -> 2104.A | B41: =_xlfn.XLOOKUP(Tabela1[[#This Row],[Processo]],'Árvore de Localização'!$D:$D,'Árvore de Localização'!$B:$B,"",0,1) -> Utilidades | C41: =_xlfn.XLOOKUP(Tabela1[[#This Row],[Processo]],'Árvore de Localização'!$D:$D,'Árvore de Localização'!$C:$C,"",0,1) -> Geração de Energia | D41: Casa de Força | E41: Casa de Força | F41: Ambas | K41: =IF(OR(Tabela1[[#This Row],[Replan]]="",Tabela1[[#This Row],[Previsto (LB)]]=""),"",Tabela1[[#This Row],[Previsto (LB)]]-Tabela1[[#This Row],[Replan]]) | L41: 1.2.12.1.2 | S41: =IF(R41="Não iniciado",1,IF(R41="Em andamento",2,3)) -> 3
A42: =_xlfn.XLOOKUP("*"&Tabela1[[#This Row],[Processo]]&"*",'Árvore de Localização'!$H:$H,'Árvore de Localização'!$G:$G,"0000",2) -> 2104.A | B42: =_xlfn.XLOOKUP(Tabela1[[#This Row],[Processo]],'Árvore de Localização'!$D:$D,'Árvore de Localização'!$B:$B,"",0,1) -> Utilidades | C42: =_xlfn.XLOOKUP(Tabela1[[#This Row],[Processo]],'Árvore de Localização'!$D:$D,'Árvore de Localização'!$C:$C,"",0,1) -> Geração de Energia | D42: Casa de Força | E42: Casa de Força | F42: Ambas | K42: =IF(OR(Tabela1[[#This Row],[Replan]]="",Tabela1[[#This Row],[Previsto (LB)]]=""),"",Tabela1[[#This Row],[Previsto (LB)]]-Tabela1[[#This Row],[Replan]]) | L42: 1.2.12.1.3 | S42: =IF(R42="Não iniciado",1,IF(R42="Em andamento",2,3)) -> 3
...

Sheet EAP Planej.
A1: Nível | B1: Descrição | C1: EDT | D1: Nome da Tarefa | E1: % concluído | F1: Duração (total) | G1: Duração (úteis int) | H1: Início | I1: Término | J1: Observação
A2: 1 | B2: PROJETO | C2: 1 | D2: SISTEMAS DE CONTROLE AMBIENTAL | E2: =IFERROR(AVERAGE(E3,E6),"") | F2: =DATEDIF(H2,I2,"D") -> 46301 | G2: =NETWORKDAYS.INTL(H2,I2) -> 33072 | H2: =MIN(H3,H6) -> 0 | I2: =MAX(I3,I6) -> 46301
A3: 2 | B3: DEPARTAMENTO | C3: 1.1 | D3: MEIO AMBIENTE | E3: =IFERROR(AVERAGE(E4,E5),"") | F3: =DATEDIF(H3,I3,"D") -> 30 | G3: =NETWORKDAYS.INTL(H3,I3) -> 22 | H3: =MIN(H4:H5) -> 46271 | I3: =MAX(I4:I5) -> 46301
A4: 3 | B4: SCA | C4: 1.1.1 | D4: PROTOCOLO DO RELATÓRIO FINAL DE OBRA | F4: =DATEDIF(H4,I4,"D") -> 0 | G4: =NETWORKDAYS.INTL(H4,I4) -> 0 | H4: =H5-30 -> 46271 | I4: =I5-30 -> 46271
A5: 3 | B5: SCA | C5: 1.1.1 | D5: VISTORIA AMBIENTAL | F5: =DATEDIF(H5,I5,"D") -> 0 | G5: =NETWORKDAYS.INTL(H5,I5) -> 1 | H5: 46301 | I5: 46301
A6: 2 | B6: DEPARTAMENTO | C6: 1.2 | D6: OBRA | E6: =IFERROR(AVERAGE(E7,E62,E117,E172,E227,E282,E345,E403,E458,E513,E568,E623,E678,E733,E821,E876,E931,E986,E1041,E1096,E1156,E1211),"") | F6: =IFERROR(DATEDIF(H6,I6,"D"),0) -> 0 | G6: =IFERROR(NETWORKDAYS.INTL(H6,I6),0) -> 0 | H6: =MIN(H7,H62,H117,H172,H227,H282,H345,H403,H458,H513,H568,H623,H678,H733,H821,H876,H931,H986,H1041,H1096,H1156,H1211) -> 0 | I6: =MAX(I7,I62,I117,I172,I227,I282,I345,I403,I458,I513,I568,I623,I678,I733,I821,I876,I931,I986,I1041,I1096,I1156,I1211) -> 0
A7: 3 | B7: ILHA DE PROCESSO | C7: 1.2.1 | D7: GERAL | E7: =IFERROR(AVERAGE(E8,E17,E26,E35,E44,E53),"") | F7: =IFERROR(DATEDIF(H7,I7,"D"),0) -> 0 | G7: =IFERROR(NETWORKDAYS.INTL(H7,I7),0) -> 0 | H7: =MIN(H8,H17,H26,H35,H44,H53) -> 0 | I7: =MAX(I8,I17,I26,I35,I44,I53) -> 0
A8: 4 | B8: DISCIPLINA | C8: 1.2.1.1 | D8: CIVIL | E8: =IFERROR(SUBTOTAL(1,E9:E16),"") | F8: =IFERROR(DATEDIF(H8,I8,"D"),0) -> 0 | G8: =IFERROR(NETWORKDAYS.INTL(H8,I8),0) -> 0 | H8: =MIN(H9:H16) -> 0 | I8: =MAX(I9:I16) -> 0
A9: 5 | B9: SCA | C9: 1.2.1.1.1 | D9: Dissipador | F9: =IFERROR(DATEDIF(H9,I9,"D"),0) -> 0 | G9: =IFERROR(NETWORKDAYS.INTL(H9,I9),0) -> 0
A10: 5 | B10: SCA | C10: 1.2.1.1.2 | D10: Vertedouro | F10: =IFERROR(DATEDIF(H10,I10,"D"),0) -> 0 | G10: =IFERROR(NETWORKDAYS.INTL(H10,I10),0) -> 0
A11: 5 | B11: SCA | C11: 1.2.1.1.3 | D11: Monge | F11: =IFERROR(DATEDIF(H11,I11,"D"),0) -> 0 | G11: =IFERROR(NETWORKDAYS.INTL(H11,I11),0) -> 0
A12: 5 | B12: SCA | C12: 1.2.1.1.4 | D12: Taludes com grama | F12: =IFERROR(DATEDIF(H12,I12,"D"),0) -> 0 | G12: =IFERROR(NETWORKDAYS.INTL(H12,I12),0) -> 0
A13: 5 | B13: SCA | C13: 1.2.1.1.5 | D13: Conexão com a drenagem da planta | F13: =IFERROR(DATEDIF(H13,I13,"D"),0) -> 0 | G13: =IFERROR(NETWORKDAYS.INTL(H13,I13),0) -> 0
A14: 5 | B14: SCA | C14: 1.2.1.1.6 | D14: Concretagem dos caminhos, ruas, fluxos de caminhões | F14: =IFERROR(DATEDIF(H14,I14,"D"),0) -> 0 | G14: =IFERROR(NETWORKDAYS.INTL(H14,I14),0) -> 0
A15: 5 | B15: SCA | C15: 1.2.1.1.7 | D15: Caixas de drenagem | F15: =IFERROR(DATEDIF(H15,I15,"D"),0) -> 0 | G15: =IFERROR(NETWORKDAYS.INTL(H15,I15),0) -> 0
A16: 5 | B16: SCA | C16: 1.2.1.1.8 | D16: Interligação nas lagoas | F16: =IFERROR(DATEDIF(H16,I16,"D"),0) -> 0 | G16: =IFERROR(NETWORKDAYS.INTL(H16,I16),0) -> 0
A17: 4 | B17: DISCIPLINA | C17: 1.2.1.2 | D17: METÁLICA | E17: =IFERROR(SUBTOTAL(1,E18:E25),"") | F17: =IFERROR(DATEDIF(H17,I17,"D"),0) -> 0 | G17: =IFERROR(NETWORKDAYS.INTL(H17,I17),0) -> 0 | H17: =MIN(H18:H25) -> 0 | I17: =MAX(I18:I25) -> 0
A18: 5 | B18: SCA | C18: 1.2.1.2.1 | F18: =IFERROR(DATEDIF(H18,I18,"D"),0) -> 0 | G18: =IFERROR(NETWORKDAYS.INTL(H18,I18),0) -> 0
A19: 5 | B19: SCA | C19: 1.2.1.2.2 | F19: =IFERROR(DATEDIF(H19,I19,"D"),0) -> 0 | G19: =IFERROR(NETWORKDAYS.INTL(H19,I19),0) -> 0
A20: 5 | B20: SCA | C20: 1.2.1.2.3 | F20: =IFERROR(DATEDIF(H20,I20,"D"),0) -> 0 | G20: =IFERROR(NETWORKDAYS.INTL(H20,I20),0) -> 0
A21: 5 | B21: SCA | C21: 1.2.1.2.4 | F21: =IFERROR(DATEDIF(H21,I21,"D"),0) -> 0 | G21: =IFERROR(NETWORKDAYS.INTL(H21,I21),0) -> 0
A22: 5 | B22: SCA | C22: 1.2.1.2.5 | F22: =IFERROR(DATEDIF(H22,I22,"D"),0) -> 0 | G22: =IFERROR(NETWORKDAYS.INTL(H22,I22),0) -> 0
A23: 5 | B23: SCA | C23: 1.2.1.2.6 | F23: =IFERROR(DATEDIF(H23,I23,"D"),0) -> 0 | G23: =IFERROR(NETWORKDAYS.INTL(H23,I23),0) -> 0
A24: 5 | B24: SCA | C24: 1.2.1.2.7 | F24: =IFERROR(DATEDIF(H24,I24,"D"),0) -> 0 | G24: =IFERROR(NETWORKDAYS.INTL(H24,I24),0) -> 0
A25: 5 | B25: SCA | C25: 1.2.1.2.8 | F25: =IFERROR(DATEDIF(H25,I25,"D"),0) -> 0 | G25: =IFERROR(NETWORKDAYS.INTL(H25,I25),0) -> 0
A26: 4 | B26: DISCIPLINA | C26: 1.2.1.3 | D26: MECÂNICA | E26: =IFERROR(SUBTOTAL(1,E27:E34),"") | F26: =IFERROR(DATEDIF(H26,I26,"D"),0) -> 0 | G26: =IFERROR(NETWORKDAYS.INTL(H26,I26),0) -> 0 | H26: =MIN(H27:H34) -> 0 | I26: =MAX(I27:I34) -> 0
A27: 5 | B27: SCA | C27: 1.2.1.3.1 | D27: Bombas instaladas | F27: =IFERROR(DATEDIF(H27,I27,"D"),0) -> 0 | G27: =IFERROR(NETWORKDAYS.INTL(H27,I27),0) -> 0
A28: 5 | B28: SCA | C28: 1.2.1.3.2 | F28: =IFERROR(DATEDIF(H28,I28,"D"),0) -> 0 | G28: =IFERROR(NETWORKDAYS.INTL(H28,I28),0) -> 0
A29: 5 | B29: SCA | C29: 1.2.1.3.3 | F29: =IFERROR(DATEDIF(H29,I29,"D"),0) -> 0 | G29: =IFERROR(NETWORKDAYS.INTL(H29,I29),0) -> 0
A30: 5 | B30: SCA | C30: 1.2.1.3.4 | F30: =IFERROR(DATEDIF(H30,I30,"D"),0) -> 0 | G30: =IFERROR(NETWORKDAYS.INTL(H30,I30),0) -> 0
A31: 5 | B31: SCA | C31: 1.2.1.3.5 | F31: =IFERROR(DATEDIF(H31,I31,"D"),0) -> 0 | G31: =IFERROR(NETWORKDAYS.INTL(H31,I31),0) -> 0
A32: 5 | B32: SCA | C32: 1.2.1.3.6 | F32: =IFERROR(DATEDIF(H32,I32,"D"),0) -> 0 | G32: =IFERROR(NETWORKDAYS.INTL(H32,I32),0) -> 0
A33: 5 | B33: SCA | C33: 1.2.1.3.7 | F33: =IFERROR(DATEDIF(H33,I33,"D"),0) -> 0 | G33: =IFERROR(NETWORKDAYS.INTL(H33,I33),0) -> 0
A34: 5 | B34: SCA | C34: 1.2.1.3.8 | F34: =IFERROR(DATEDIF(H34,I34,"D"),0) -> 0 | G34: =IFERROR(NETWORKDAYS.INTL(H34,I34),0) -> 0
A35: 4 | B35: DISCIPLINA | C35: 1.2.1.4 | D35: ELÉTRICA | E35: =IFERROR(SUBTOTAL(1,E36:E43),"") | F35: =IFERROR(DATEDIF(H35,I35,"D"),0) -> 0 | G35: =IFERROR(NETWORKDAYS.INTL(H35,I35),0) -> 0 | H35: =MIN(H36:H43) -> 0 | I35: =MAX(I36:I43) -> 0
A36: 5 | B36: SCA | C36: 1.2.1.4.1 | F36: =IFERROR(DATEDIF(H36,I36,"D"),0) -> 0 | G36: =IFERROR(NETWORKDAYS.INTL(H36,I36),0) -> 0
A37: 5 | B37: SCA | C37: 1.2.1.4.2 | F37: =IFERROR(DATEDIF(H37,I37,"D"),0) -> 0 | G37: =IFERROR(NETWORKDAYS.INTL(H37,I37),0) -> 0
A38: 5 | B38: SCA | C38: 1.2.1.4.3 | F38: =IFERROR(DATEDIF(H38,I38,"D"),0) -> 0 | G38: =IFERROR(NETWORKDAYS.INTL(H38,I38),0) -> 0
A39: 5 | B39: SCA | C39: 1.2.1.4.4 | F39: =IFERROR(DATEDIF(H39,I39,"D"),0) -> 0 | G39: =IFERROR(NETWORKDAYS.INTL(H39,I39),0) -> 0
A40: 5 | B40: SCA | C40: 1.2.1.4.5 | F40: =IFERROR(DATEDIF(H40,I40,"D"),0) -> 0 | G40: =IFERROR(NETWORKDAYS.INTL(H40,I40),0) -> 0
...

Sheet Árvore de Localização
B2: MACRO ÁREA | C2: ILHA DE PROCESSO | D2: PROCESSO | F2: TIPO | G2: CÓDIGO | H2: DESCRIÇÃO | I2: CÓDIGO + DESCRIÇÃO
B3: Geral | C3: Geral | D3: Pipe Rack | F3: Macro área | G3: 21. | H3: Geral | I3: =_xlfn.CONCAT(G3," ",H3) -> 21. Geral
B4: Geral | C4: Geral | D4: Terraplenagem | F4: Ilha de processo de processo | G4: 2100. | H4: Geral | I4: =_xlfn.CONCAT(G4," ",H4) -> 2100. Geral
B5: Geral | C5: Geral | D5: Drenagem | F5: Processo | G5: 2100.A | H5: Pipe Rack | I5: =_xlfn.CONCAT(G5," ",H5) -> 2100.A Pipe Rack
B6: Geral | C6: Geral | D6: Pavimentação | F6: Processo | G6: 2100.B | H6: Terraplenagem (Camada Vegetal, Tratamento de Sub-Leito, Compactação de Aterro) | I6: =_xlfn.CONCAT(G6," ",H6) -> 2100.B Terraplenagem (Camada Vegetal, Tratamento de Sub-Leito, Compactação de Aterro)
B7: Geral | C7: Geral | D7: Hangar | F7: Processo | G7: 2100.C | H7: Drenagem (Boca de Lobo, Poço de Visita, Caixa de Coleta, Tubo, Meio Fio) | I7: =_xlfn.CONCAT(G7," ",H7) -> 2100.C Drenagem (Boca de Lobo, Poço de Visita, Caixa de Coleta, Tubo, Meio Fio)
B8: Geral | C8: Geral | D8: Dissipador | F8: Processo | G8: 2100.D | H8: Pavimentação (Cascalho, Tratamento de Sub-Base e Base, Imprimação, CBUQ) | I8: =_xlfn.CONCAT(G8," ",H8) -> 2100.D Pavimentação (Cascalho, Tratamento de Sub-Base e Base, Imprimação, CBUQ)
B9: Geral | C9: Geral | D9: Trevo de Acesso | F9: Processo | G9: 2100.E | H9: Hangar (Aeroporto) | I9: =_xlfn.CONCAT(G9," ",H9) -> 2100.E Hangar (Aeroporto)
B10: Etanol | C10: Moinho de Grãos | D10: =C10 -> Moinho de Grãos | F10: Processo | G10: 2100.H | H10: Reservatório de Detenção de Água Pluvial (Dissipador) | I10: =_xlfn.CONCAT(G10," ",H10) -> 2100.H Reservatório de Detenção de Água Pluvial (Dissipador)
B11: Etanol | C11: Cozimento | D11: Mash Milling | F11: Processo | G11: 2100.I | H11: Trevo de Acesso | I11: =_xlfn.CONCAT(G11," ",H11) -> 2100.I Trevo de Acesso
B12: Etanol | C12: Cozimento | D12: Liquefação | F12: Macro área | G12: 21B. | H12: Etanol | I12: =_xlfn.CONCAT(G12," ",H12) -> 21B. Etanol
B13: Etanol | C13: Cozimento | D13: Dióxido de Cloro | F13: Ilha de processo | G13: 2111. | H13: Moinho de Grãos | I13: =_xlfn.CONCAT(G13," ",H13) -> 2111. Moinho de Grãos
B14: Etanol | C14: Cozimento | D14: Selective Grind Technology (SGT) | F14: Ilha de processo | G14: 2102. | H14: Cozimento | I14: =_xlfn.CONCAT(G14," ",H14) -> 2102. Cozimento
B15: Etanol | C15: Cozimento | D15: Clean In Place (CIP) | F15: Processo | G15: 2102.A | H15: Mash Milling | I15: =_xlfn.CONCAT(G15," ",H15) -> 2102.A Mash Milling
B16: Etanol | C16: Fermentação | D16: Propagação do Fermento | F16: Processo | G16: 2102.B | H16: Liquefação | I16: =_xlfn.CONCAT(G16," ",H16) -> 2102.B Liquefação
B17: Etanol | C17: Fermentação | D17: Dornas de Fermentação | F17: Processo | G17: 2102.C | H17: Dióxido de Cloro | I17: =_xlfn.CONCAT(G17," ",H17) -> 2102.C Dióxido de Cloro
B18: Etanol | C18: Fermentação | D18: Recuperação de CO₂ | F18: Processo | G18: 2102.D | H18: Selective Grind Technology (SGT) | I18: =_xlfn.CONCAT(G18," ",H18) -> 2102.D Selective Grind Technology (SGT)
B19: Etanol | C19: Fermentação | D19: Químicos | F19: Processo | G19: 2102.E | H19: Clean In Place (CIP) | I19: =_xlfn.CONCAT(G19," ",H19) -> 2102.E Clean In Place (CIP)
B20: Etanol | C20: Fermentação | D20: Enzimas | F20: Macro área | G20: 2106. | H20: Fermentação | I20: =_xlfn.CONCAT(G20," ",H20) -> 2106. Fermentação
B21: Etanol | C21: Destilaria | D21: Dorna Volante | F21: Ilha de processo | G21: 2106.A | H21: Propagação do Fermento | I21: =_xlfn.CONCAT(G21," ",H21) -> 2106.A Propagação do Fermento
B22: Etanol | C22: Destilaria | D22: Destilaria de Etanol Hidratado | F22: Processo | G22: 2106.B | H22: Dornas de Fermentação | I22: =_xlfn.CONCAT(G22," ",H22) -> 2106.B Dornas de Fermentação
... B52: Utilidades | C52: Sistema de Combate a Incêndio | D52: SPCI | F52: Ilha de processo | G52: 2101. | H52: Geração de Vapor | I52: =_xlfn.CONCAT(G52," ",H52) -> 2101. Geração de Vapor
B53: Utilidades | C53: Sistema de Selagem | D53: =C53 -> Sistema de Selagem | F53: Processo | G53: 2101.A | H53: Caldeira | I53: =_xlfn.CONCAT(G53," ",H53) -> 2101.A Caldeira
B54: Grãos | C54: Recebimento de Grãos | D54: Classificação | F54: Processo | G54: 2101.B | H54: Armazenamento de Água Desmineralizada | I54: =_xlfn.CONCAT(G54," ",H54) -> 2101.B Armazenamento de Água Desmineralizada
B55: Grãos | C55: Recebimento de Grãos | D55: Balança Rodoviária | F55: Processo | G55: 2101.C | H55: Estação Redutora de Pressão | I55: =_xlfn.CONCAT(G55," ",H55) -> 2101.C Estação Redutora de Pressão
B56: Grãos | C56: Recebimento de Grãos | D56: Faturamento | F56: Processo | G56: 2101.D | H56: Caldeira de Cinzas | I56: =_xlfn.CONCAT(G56," ",H56) -> 2101.D Caldeira de Cinzas
B57: Grãos | C57: Descarregamento e Armazenamento de Grãos | D57: Tombador | F57: Ilha de processo | G57: 2104. | H57: Geração de Energia | I57: =_xlfn.CONCAT(G57," ",H57) -> 2104. Geração de Energia
B58: Grãos | C58: Descarregamento e Armazenamento de Grãos | D58: Casa de Máquinas | F58: Processo | G58: 2104.A | H58: Casa de Força | I58: =_xlfn.CONCAT(G58," ",H58) -> 2104.A Casa de Força
B59: Grãos | C59: Descarregamento e Armazenamento de Grãos | D59: Pré-Limpeza | F59: Processo | G59: 2104.B | H59: Subestação e Distribuição de Energia | I59: =_xlfn.CONCAT(G59," ",H59) -> 2104.B Subestação e Distribuição de Energia
B60: Grãos | C60: Descarregamento e Armazenamento de Grãos | D60: Moega | F60: Ilha de processo | G60: 2121. | H60: Sistema de Geração de Ar Comprimido | I60: =_xlfn.CONCAT(G60," ",H60) -> 2121. Sistema de Geração de Ar Comprimido
B61: Grãos | C61: Descarregamento e Armazenamento de Grãos | D61: Elevador | F61: Processo | G61: 2121.A | H61: Geração e Distribuição de Ar Comprimido | I61: =_xlfn.CONCAT(G61," ",H61) -> 2121.A Geração e Distribuição de Ar Comprimido
B62: Grãos | C62: Descarregamento e Armazenamento de Grãos | D62: Armazenamento de Grãos | F62: Ilha de processo | G62: 2110. | H62: Estação de Tratamento de Água (ETA) | I62: =_xlfn.CONCAT(G62," ",H62) -> 2110. Estação de Tratamento de Água (ETA)
B63: Grãos | C63: Descarregamento e Armazenamento de Grãos | D63: Secagem de Grãos | F63: Processo | G63: 2110.A | H63: Poços Artesianos | I63: =_xlfn.CONCAT(G63," ",H63) -> 2110.A Poços Artesianos
B64: Administração | C64: Administração | D64: Portaria | F64: Processo | G64: 2110.B | H64: Osmose | I64: =_xlfn.CONCAT(G64," ",H64) -> 2110.B Osmose
B65: Administração | C65: Administração | D65: Vestiário | F65: Processo | G65: 2110.C | H65: Armazenamento de Água Bruta | I65: =_xlfn.CONCAT(G65," ",H65) -> 2110.C Armazenamento de Água Bruta
... B89: Efluentes | C89: Estação de Tratamento de Efluentes (ETE) | D89: Fertirrigação | F89: Processo | G89: 2123.G | H89: Oficina de Lubrificação | I89: =_xlfn.CONCAT(G89," ",H89) -> 2123.G Oficina de Lubrificação
F90: Processo | G90: 2123.H | H90: Manutenção Industrial (Oficina Mecânica) | I90: =_xlfn.CONCAT(G90," ",H90) -> 2123.H Manutenção Industrial (Oficina Mecânica)
F91: Processo | G91: 2123.I | H91: Escritório Administrativo | I91: =_xlfn.CONCAT(G91," ",H91) -> 2123.I Escritório Administrativo
F92: Macro área | G92: 21H. | H92: Laboratórios | I92: =_xlfn.CONCAT(G92," ",H92) -> 21H. Laboratórios
F93: Ilha de processo | G93: 2126. | H93: Laboratórios | I93: =_xlfn.CONCAT(G93," ",H93) -> 2126. Laboratórios
...
